2024-04-28 09:19:57,105 INFO: Application startup [in D:\pythoncrawl\flask\app.py:30]
2024-04-28 09:21:04,696 ERROR: Failed to scrape: Message: unknown error: Failed to create Chrome process.
Stacktrace:
	GetHandleVerifier [0x009AC113+48259]
	(No symbol) [0x0093CA41]
	(No symbol) [0x00830A17]
	(No symbol) [0x0085CA0D]
	(No symbol) [0x00859239]
	(No symbol) [0x0089A8BA]
	(No symbol) [0x0089A0EA]
	(No symbol) [0x00890B36]
	(No symbol) [0x0086570D]
	(No symbol) [0x008662CD]
	GetHandleVerifier [0x00C66533+2908323]
	GetHandleVerifier [0x00CA3B4B+3159739]
	GetHandleVerifier [0x00A4505B+674763]
	GetHandleVerifier [0x00A4B21C+699788]
	(No symbol) [0x00946244]
	(No symbol) [0x00942298]
	(No symbol) [0x0094242C]
	(No symbol) [0x00934BB0]
	BaseThreadInitThunk [0x766A7BA9+25]
	RtlInitializeExceptionChain [0x778BBE3B+107]
	RtlClearBits [0x778BBDBF+191]
 [in D:\pythoncrawl\flask\app.py:183]
Traceback (most recent call last):
  File "D:\pythoncrawl\flask\app.py", line 180, in manual_scrape
    scheduled_scrape()
  File "D:\pythoncrawl\flask\app.py", line 43, in scheduled_scrape
    men_deals = scrape_deals(men_url, men_deals_collection, max_items=30)
                ^^^^^^^^^^^^^^^^^^^^^^^^^^^^^^^^^^^^^^^^^^^^^^^^^^^^^^^^^
  File "D:\pythoncrawl\flask\app.py", line 80, in scrape_deals
    driver = Chrome(service=Service(ChromeDriverManager().install()), options=chrome_options)
             ^^^^^^^^^^^^^^^^^^^^^^^^^^^^^^^^^^^^^^^^^^^^^^^^^^^^^^^^^^^^^^^^^^^^^^^^^^^^^^^^
  File "C:\Users\CoeurK97\AppData\Local\Programs\Python\Python311\Lib\site-packages\selenium\webdriver\chrome\webdriver.py", line 45, in __init__
    super().__init__(
  File "C:\Users\CoeurK97\AppData\Local\Programs\Python\Python311\Lib\site-packages\selenium\webdriver\chromium\webdriver.py", line 61, in __init__
    super().__init__(command_executor=executor, options=options)
  File "C:\Users\CoeurK97\AppData\Local\Programs\Python\Python311\Lib\site-packages\selenium\webdriver\remote\webdriver.py", line 208, in __init__
    self.start_session(capabilities)
  File "C:\Users\CoeurK97\AppData\Local\Programs\Python\Python311\Lib\site-packages\selenium\webdriver\remote\webdriver.py", line 292, in start_session
    response = self.execute(Command.NEW_SESSION, caps)["value"]
               ^^^^^^^^^^^^^^^^^^^^^^^^^^^^^^^^^^^^^^^
  File "C:\Users\CoeurK97\AppData\Local\Programs\Python\Python311\Lib\site-packages\selenium\webdriver\remote\webdriver.py", line 347, in execute
    self.error_handler.check_response(response)
  File "C:\Users\CoeurK97\AppData\Local\Programs\Python\Python311\Lib\site-packages\selenium\webdriver\remote\errorhandler.py", line 229, in check_response
    raise exception_class(message, screen, stacktrace)
selenium.common.exceptions.WebDriverException: Message: unknown error: Failed to create Chrome process.
Stacktrace:
	GetHandleVerifier [0x009AC113+48259]
	(No symbol) [0x0093CA41]
	(No symbol) [0x00830A17]
	(No symbol) [0x0085CA0D]
	(No symbol) [0x00859239]
	(No symbol) [0x0089A8BA]
	(No symbol) [0x0089A0EA]
	(No symbol) [0x00890B36]
	(No symbol) [0x0086570D]
	(No symbol) [0x008662CD]
	GetHandleVerifier [0x00C66533+2908323]
	GetHandleVerifier [0x00CA3B4B+3159739]
	GetHandleVerifier [0x00A4505B+674763]
	GetHandleVerifier [0x00A4B21C+699788]
	(No symbol) [0x00946244]
	(No symbol) [0x00942298]
	(No symbol) [0x0094242C]
	(No symbol) [0x00934BB0]
	BaseThreadInitThunk [0x766A7BA9+25]
	RtlInitializeExceptionChain [0x778BBE3B+107]
	RtlClearBits [0x778BBDBF+191]

2024-04-28 09:22:00,631 INFO: Application startup [in D:\pythoncrawl\flask\app.py:30]
2024-04-28 09:25:10,390 ERROR: Failed to scrape: ('Connection aborted.', ConnectionResetError(10054, '远程主机强迫关闭了一个现有的连接。', None, 10054, None)) [in D:\pythoncrawl\flask\app.py:183]
Traceback (most recent call last):
  File "C:\Users\CoeurK97\AppData\Local\Programs\Python\Python311\Lib\site-packages\urllib3\connectionpool.py", line 703, in urlopen
    httplib_response = self._make_request(
                       ^^^^^^^^^^^^^^^^^^^
  File "C:\Users\CoeurK97\AppData\Local\Programs\Python\Python311\Lib\site-packages\urllib3\connectionpool.py", line 449, in _make_request
    six.raise_from(e, None)
  File "<string>", line 3, in raise_from
  File "C:\Users\CoeurK97\AppData\Local\Programs\Python\Python311\Lib\site-packages\urllib3\connectionpool.py", line 444, in _make_request
    httplib_response = conn.getresponse()
                       ^^^^^^^^^^^^^^^^^^
  File "C:\Users\CoeurK97\AppData\Local\Programs\Python\Python311\Lib\http\client.py", line 1374, in getresponse
    response.begin()
  File "C:\Users\CoeurK97\AppData\Local\Programs\Python\Python311\Lib\http\client.py", line 318, in begin
    version, status, reason = self._read_status()
                              ^^^^^^^^^^^^^^^^^^^
  File "C:\Users\CoeurK97\AppData\Local\Programs\Python\Python311\Lib\http\client.py", line 279, in _read_status
    line = str(self.fp.readline(_MAXLINE + 1), "iso-8859-1")
               ^^^^^^^^^^^^^^^^^^^^^^^^^^^^^^
  File "C:\Users\CoeurK97\AppData\Local\Programs\Python\Python311\Lib\socket.py", line 706, in readinto
    return self._sock.recv_into(b)
           ^^^^^^^^^^^^^^^^^^^^^^^
ConnectionResetError: [WinError 10054] 远程主机强迫关闭了一个现有的连接。

During handling of the above exception, another exception occurred:

Traceback (most recent call last):
  File "D:\pythoncrawl\flask\app.py", line 180, in manual_scrape
    scheduled_scrape()
  File "D:\pythoncrawl\flask\app.py", line 43, in scheduled_scrape
    men_deals = scrape_deals(men_url, men_deals_collection, max_items=30)
                ^^^^^^^^^^^^^^^^^^^^^^^^^^^^^^^^^^^^^^^^^^^^^^^^^^^^^^^^^
  File "D:\pythoncrawl\flask\app.py", line 82, in scrape_deals
    driver.get(url)
  File "C:\Users\CoeurK97\AppData\Local\Programs\Python\Python311\Lib\site-packages\selenium\webdriver\remote\webdriver.py", line 356, in get
    self.execute(Command.GET, {"url": url})
  File "C:\Users\CoeurK97\AppData\Local\Programs\Python\Python311\Lib\site-packages\selenium\webdriver\remote\webdriver.py", line 345, in execute
    response = self.command_executor.execute(driver_command, params)
               ^^^^^^^^^^^^^^^^^^^^^^^^^^^^^^^^^^^^^^^^^^^^^^^^^^^^^
  File "C:\Users\CoeurK97\AppData\Local\Programs\Python\Python311\Lib\site-packages\selenium\webdriver\remote\remote_connection.py", line 302, in execute
    return self._request(command_info[0], url, body=data)
           ^^^^^^^^^^^^^^^^^^^^^^^^^^^^^^^^^^^^^^^^^^^^^^
  File "C:\Users\CoeurK97\AppData\Local\Programs\Python\Python311\Lib\site-packages\selenium\webdriver\remote\remote_connection.py", line 322, in _request
    response = self._conn.request(method, url, body=body, headers=headers)
               ^^^^^^^^^^^^^^^^^^^^^^^^^^^^^^^^^^^^^^^^^^^^^^^^^^^^^^^^^^^
  File "C:\Users\CoeurK97\AppData\Local\Programs\Python\Python311\Lib\site-packages\urllib3\request.py", line 78, in request
    return self.request_encode_body(
           ^^^^^^^^^^^^^^^^^^^^^^^^^
  File "C:\Users\CoeurK97\AppData\Local\Programs\Python\Python311\Lib\site-packages\urllib3\request.py", line 170, in request_encode_body
    return self.urlopen(method, url, **extra_kw)
           ^^^^^^^^^^^^^^^^^^^^^^^^^^^^^^^^^^^^^
  File "C:\Users\CoeurK97\AppData\Local\Programs\Python\Python311\Lib\site-packages\urllib3\poolmanager.py", line 376, in urlopen
    response = conn.urlopen(method, u.request_uri, **kw)
               ^^^^^^^^^^^^^^^^^^^^^^^^^^^^^^^^^^^^^^^^^
  File "C:\Users\CoeurK97\AppData\Local\Programs\Python\Python311\Lib\site-packages\urllib3\connectionpool.py", line 787, in urlopen
    retries = retries.increment(
              ^^^^^^^^^^^^^^^^^^
  File "C:\Users\CoeurK97\AppData\Local\Programs\Python\Python311\Lib\site-packages\urllib3\util\retry.py", line 550, in increment
    raise six.reraise(type(error), error, _stacktrace)
          ^^^^^^^^^^^^^^^^^^^^^^^^^^^^^^^^^^^^^^^^^^^^
  File "C:\Users\CoeurK97\AppData\Local\Programs\Python\Python311\Lib\site-packages\urllib3\packages\six.py", line 769, in reraise
    raise value.with_traceback(tb)
  File "C:\Users\CoeurK97\AppData\Local\Programs\Python\Python311\Lib\site-packages\urllib3\connectionpool.py", line 703, in urlopen
    httplib_response = self._make_request(
                       ^^^^^^^^^^^^^^^^^^^
  File "C:\Users\CoeurK97\AppData\Local\Programs\Python\Python311\Lib\site-packages\urllib3\connectionpool.py", line 449, in _make_request
    six.raise_from(e, None)
  File "<string>", line 3, in raise_from
  File "C:\Users\CoeurK97\AppData\Local\Programs\Python\Python311\Lib\site-packages\urllib3\connectionpool.py", line 444, in _make_request
    httplib_response = conn.getresponse()
                       ^^^^^^^^^^^^^^^^^^
  File "C:\Users\CoeurK97\AppData\Local\Programs\Python\Python311\Lib\http\client.py", line 1374, in getresponse
    response.begin()
  File "C:\Users\CoeurK97\AppData\Local\Programs\Python\Python311\Lib\http\client.py", line 318, in begin
    version, status, reason = self._read_status()
                              ^^^^^^^^^^^^^^^^^^^
  File "C:\Users\CoeurK97\AppData\Local\Programs\Python\Python311\Lib\http\client.py", line 279, in _read_status
    line = str(self.fp.readline(_MAXLINE + 1), "iso-8859-1")
               ^^^^^^^^^^^^^^^^^^^^^^^^^^^^^^
  File "C:\Users\CoeurK97\AppData\Local\Programs\Python\Python311\Lib\socket.py", line 706, in readinto
    return self._sock.recv_into(b)
           ^^^^^^^^^^^^^^^^^^^^^^^
urllib3.exceptions.ProtocolError: ('Connection aborted.', ConnectionResetError(10054, '远程主机强迫关闭了一个现有的连接。', None, 10054, None))
2024-04-28 09:25:14,992 INFO: Application startup [in D:\pythoncrawl\flask\app.py:30]
2024-04-28 09:35:35,910 INFO: Application startup [in D:\pythoncrawl\flask\app.py:30]
2024-04-28 09:38:41,146 INFO: Application startup [in D:\pythoncrawl\flask\app.py:30]
