2024-04-28 11:10:27,858 ERROR: Failed to scrape: HTTPSConnectionPool(host='www.dealmoon.com', port=443): Max retries exceeded with url: /en/up-to-70-off-extra-20-off-the-outnet-zimmermann-women-dress-sale/4171154.html (Caused by ProxyError('Cannot connect to proxy.', NewConnectionError('<urllib3.connection.HTTPSConnection object at 0x000002DB0B9D2C10>: Failed to establish a new connection: [WinError 10061] 由于目标计算机积极拒绝，无法连接。'))) [in D:\pythoncrawl\flask\app.py:183]
Traceback (most recent call last):
  File "C:\Users\CoeurK97\AppData\Local\Programs\Python\Python311\Lib\site-packages\urllib3\connection.py", line 174, in _new_conn
    conn = connection.create_connection(
           ^^^^^^^^^^^^^^^^^^^^^^^^^^^^^
  File "C:\Users\CoeurK97\AppData\Local\Programs\Python\Python311\Lib\site-packages\urllib3\util\connection.py", line 95, in create_connection
    raise err
  File "C:\Users\CoeurK97\AppData\Local\Programs\Python\Python311\Lib\site-packages\urllib3\util\connection.py", line 85, in create_connection
    sock.connect(sa)
ConnectionRefusedError: [WinError 10061] 由于目标计算机积极拒绝，无法连接。

During handling of the above exception, another exception occurred:

Traceback (most recent call last):
  File "C:\Users\CoeurK97\AppData\Local\Programs\Python\Python311\Lib\site-packages\urllib3\connectionpool.py", line 700, in urlopen
    self._prepare_proxy(conn)
  File "C:\Users\CoeurK97\AppData\Local\Programs\Python\Python311\Lib\site-packages\urllib3\connectionpool.py", line 996, in _prepare_proxy
    conn.connect()
  File "C:\Users\CoeurK97\AppData\Local\Programs\Python\Python311\Lib\site-packages\urllib3\connection.py", line 358, in connect
    self.sock = conn = self._new_conn()
                       ^^^^^^^^^^^^^^^^
  File "C:\Users\CoeurK97\AppData\Local\Programs\Python\Python311\Lib\site-packages\urllib3\connection.py", line 186, in _new_conn
    raise NewConnectionError(
urllib3.exceptions.NewConnectionError: <urllib3.connection.HTTPSConnection object at 0x000002DB0B9D2C10>: Failed to establish a new connection: [WinError 10061] 由于目标计算机积极拒绝，无法连接。

During handling of the above exception, another exception occurred:

Traceback (most recent call last):
  File "C:\Users\CoeurK97\AppData\Local\Programs\Python\Python311\Lib\site-packages\requests\adapters.py", line 486, in send
    resp = conn.urlopen(
           ^^^^^^^^^^^^^
  File "C:\Users\CoeurK97\AppData\Local\Programs\Python\Python311\Lib\site-packages\urllib3\connectionpool.py", line 787, in urlopen
    retries = retries.increment(
              ^^^^^^^^^^^^^^^^^^
  File "C:\Users\CoeurK97\AppData\Local\Programs\Python\Python311\Lib\site-packages\urllib3\util\retry.py", line 592, in increment
    raise MaxRetryError(_pool, url, error or ResponseError(cause))
urllib3.exceptions.MaxRetryError: HTTPSConnectionPool(host='www.dealmoon.com', port=443): Max retries exceeded with url: /en/up-to-70-off-extra-20-off-the-outnet-zimmermann-women-dress-sale/4171154.html (Caused by ProxyError('Cannot connect to proxy.', NewConnectionError('<urllib3.connection.HTTPSConnection object at 0x000002DB0B9D2C10>: Failed to establish a new connection: [WinError 10061] 由于目标计算机积极拒绝，无法连接。')))

During handling of the above exception, another exception occurred:

Traceback (most recent call last):
  File "D:\pythoncrawl\flask\app.py", line 180, in manual_scrape
    scheduled_scrape()
  File "D:\pythoncrawl\flask\app.py", line 46, in scheduled_scrape
    women_deals = scrape_deals(women_url, women_deals_collection, max_items=100)
                  ^^^^^^^^^^^^^^^^^^^^^^^^^^^^^^^^^^^^^^^^^^^^^^^^^^^^^^^^^^^^^^
  File "D:\pythoncrawl\flask\app.py", line 112, in scrape_deals
    detail_response = requests.get(title_link, headers=headers)
                      ^^^^^^^^^^^^^^^^^^^^^^^^^^^^^^^^^^^^^^^^^
  File "C:\Users\CoeurK97\AppData\Local\Programs\Python\Python311\Lib\site-packages\requests\api.py", line 73, in get
    return request("get", url, params=params, **kwargs)
           ^^^^^^^^^^^^^^^^^^^^^^^^^^^^^^^^^^^^^^^^^^^^
  File "C:\Users\CoeurK97\AppData\Local\Programs\Python\Python311\Lib\site-packages\requests\api.py", line 59, in request
    return session.request(method=method, url=url, **kwargs)
           ^^^^^^^^^^^^^^^^^^^^^^^^^^^^^^^^^^^^^^^^^^^^^^^^^
  File "C:\Users\CoeurK97\AppData\Local\Programs\Python\Python311\Lib\site-packages\requests\sessions.py", line 589, in request
    resp = self.send(prep, **send_kwargs)
           ^^^^^^^^^^^^^^^^^^^^^^^^^^^^^^
  File "C:\Users\CoeurK97\AppData\Local\Programs\Python\Python311\Lib\site-packages\requests\sessions.py", line 703, in send
    r = adapter.send(request, **kwargs)
        ^^^^^^^^^^^^^^^^^^^^^^^^^^^^^^^
  File "C:\Users\CoeurK97\AppData\Local\Programs\Python\Python311\Lib\site-packages\requests\adapters.py", line 513, in send
    raise ProxyError(e, request=request)
requests.exceptions.ProxyError: HTTPSConnectionPool(host='www.dealmoon.com', port=443): Max retries exceeded with url: /en/up-to-70-off-extra-20-off-the-outnet-zimmermann-women-dress-sale/4171154.html (Caused by ProxyError('Cannot connect to proxy.', NewConnectionError('<urllib3.connection.HTTPSConnection object at 0x000002DB0B9D2C10>: Failed to establish a new connection: [WinError 10061] 由于目标计算机积极拒绝，无法连接。')))
2024-04-28 11:15:42,805 INFO: Application startup [in D:\pythoncrawl\flask\app.py:30]
2024-04-28 11:17:48,315 INFO: Application startup [in D:\pythoncrawl\flask\app.py:30]
2024-04-28 11:20:10,047 INFO: Application startup [in D:\pythoncrawl\flask\app.py:30]
2024-04-28 11:23:28,671 INFO: Application startup [in D:\pythoncrawl\flask\app.py:30]
2024-04-28 11:33:51,078 INFO: Application startup [in D:\pythoncrawl\flask\app.py:30]
2024-04-28 11:41:14,577 INFO: Application startup [in D:\pythoncrawl\flask\app.py:30]
2024-05-02 20:47:51,666 INFO: Application startup [in C:\Users\Carrylee\Desktop\fAIshion intern\flask\flask\app.py:30]
2024-05-02 20:47:52,177 INFO: Application startup [in C:\Users\Carrylee\Desktop\fAIshion intern\flask\flask\app.py:30]
2024-05-02 21:11:52,634 INFO: Application startup [in C:\Users\Carrylee\Desktop\fAIshion intern\flask\flask\app.py:30]
2024-05-02 21:11:53,143 INFO: Application startup [in C:\Users\Carrylee\Desktop\fAIshion intern\flask\flask\app.py:30]
